import { async } from 'regenerator-runtime';
import { TIMEOUT_SEC } from './config.js';

const timeout = function (s) {
  return new Promise(function (_, reject) {
    setTimeout(function () {
      reject(new Error(`Request took too long! Timeout after ${s} second`));
    }, s * 1000);
  });
};

export const AJAX = async function (url, uploadData = undefined) {
  try {
    const fetchPro = uploadData
      ? fetch(url, {
          method: 'POST',
          headers: {
            'Content-Type': 'application/json',
          },
          body: JSON.stringify(uploadData),
        })
      : fetch(url);

    const res = await Promise.race([fetchPro, timeout(TIMEOUT_SEC)]);
    const data = await res.json();

    if (!res.ok) throw new Error(`${data.message} (${res.status})`);
    return data;
  } catch (err) {
    throw err;
    //‚≠êüëâ Remember whenever one async function calling another then error handling is neccessory for rethrhow the error for to see main error in the original async funciton.
  }
};

/*
export const getJSON = async function (url) {
  try {
    const fetchPro = fetch(url);
    const res = await Promise.race([fetchPro, timeout(TIMEOUT_SEC)]);
    const data = await res.json();

    if (!res.ok) throw new Error(`${data.message} (${res.status})`);
    return data;
  } catch (err) {
    throw err;
  }
};

export const sendJSON = async function (url, uploadData) {
  try {
    const fetchPro = fetch(url, {
      method: 'POST',
      headers: {
        'Content-Type': 'application/json',
      },
      body: JSON.stringify(uploadData),
    });

    const res = await Promise.race([fetchPro, timeout(TIMEOUT_SEC)]);
    const data = await res.json();

    if (!res.ok) throw new Error(`${data.message} (${res.status})`);
    return data;
  } catch (err) {
    throw err;
  }
};
*/

//Previous getJson and SendJSON are i deleted so check the final file for clarification if you don't understand.
